Workbook

Sheet 📊 Сводка Руководству
B2: СВОДНЫЙ ОТЧЕТ ПО ИНФЛЮЕНСЕРАМ И АУДИТУ СПЕЦИАЛИСТОВ
B3: Фиксация метрик на текущий момент | Рабочее время залива: 10:00 - 19:00 МСК
B5: АКТИВНЫХ АККАУНТОВ | D5: ВЫЛОЖЕНО ЗА ДЕНЬ (10-19ч) | F5: ОБЩИЕ ПРОСМОТРЫ | H5: СУММАРНО ПОДПИСЧИКОВ
B6: =COUNTIF('📋 Детальный реестр'!F3:F62, "Активен") & " из " & COUNTA('📋 Детальный реестр'!F3:F62) | D6: =SUM('📋 Детальный реестр'!H3:H62) | F6: =SUM('📋 Детальный реестр'!I3:I62) | H6: =SUM('📋 Детальный реестр'!M3:M62)
B9: СВОДКА ПО ИНФЛЮЕНСЕРАМ (ТОП-10)
B10: № | C10: Инфлюенсер | D10: Ответственный спец | E10: Активных акк. | F10: Забанено | G10: Выложено сегодня (10-19ч) | H10: Всего постов | I10: Сумма просмотров | J10: Сумма подписчиков | K10: Статус аудита
B11: 1 | C11: =INDEX('📋 Детальный реестр'!B3:B8, 1) | D11: =INDEX('📋 Детальный реестр'!C3:C8, 1) | E11: =COUNTIF('📋 Детальный реестр'!F3:F8, "Активен") | F11: =COUNTIF('📋 Детальный реестр'!F3:F8, "БАН") | G11: =SUM('📋 Детальный реестр'!H3:H8) | H11: =SUM('📋 Детальный реестр'!G3:G8) | I11: =SUM('📋 Детальный реестр'!I3:I8) | J11: =SUM('📋 Детальный реестр'!M3:M8) | K11: =INDEX('🔍 Аудит и сверка спецов'!I3, 1)
B12: 2 | C12: =INDEX('📋 Детальный реестр'!B9:B14, 1) | D12: =INDEX('📋 Детальный реестр'!C9:C14, 1) | E12: =COUNTIF('📋 Детальный реестр'!F9:F14, "Активен") | F12: =COUNTIF('📋 Детальный реестр'!F9:F14, "БАН") | G12: =SUM('📋 Детальный реестр'!H9:H14) | H12: =SUM('📋 Детальный реестр'!G9:G14) | I12: =SUM('📋 Детальный реестр'!I9:I14) | J12: =SUM('📋 Детальный реестр'!M9:M14) | K12: =INDEX('🔍 Аудит и сверка спецов'!I4, 1)
B13: 3 | C13: =INDEX('📋 Детальный реестр'!B15:B20, 1) | D13: =INDEX('📋 Детальный реестр'!C15:C20, 1) | E13: =COUNTIF('📋 Детальный реестр'!F15:F20, "Активен") | F13: =COUNTIF('📋 Детальный реестр'!F15:F20, "БАН") | G13: =SUM('📋 Детальный реестр'!H15:H20) | H13: =SUM('📋 Детальный реестр'!G15:G20) | I13: =SUM('📋 Детальный реестр'!I15:I20) | J13: =SUM('📋 Детальный реестр'!M15:M20) | K13: =INDEX('🔍 Аудит и сверка спецов'!I5, 1)
B14: 4 | C14: =INDEX('📋 Детальный реестр'!B21:B26, 1) | D14: =INDEX('📋 Детальный реестр'!C21:C26, 1) | E14: =COUNTIF('📋 Детальный реестр'!F21:F26, "Активен") | F14: =COUNTIF('📋 Детальный реестр'!F21:F26, "БАН") | G14: =SUM('📋 Детальный реестр'!H21:H26) | H14: =SUM('📋 Детальный реестр'!G21:G26) | I14: =SUM('📋 Детальный реестр'!I21:I26) | J14: =SUM('📋 Детальный реестр'!M21:M26) | K14: =INDEX('🔍 Аудит и сверка спецов'!I6, 1)
B15: 5 | C15: =INDEX('📋 Детальный реестр'!B27:B32, 1) | D15: =INDEX('📋 Детальный реестр'!C27:C32, 1) | E15: =COUNTIF('📋 Детальный реестр'!F27:F32, "Активен") | F15: =COUNTIF('📋 Детальный реестр'!F27:F32, "БАН") | G15: =SUM('📋 Детальный реестр'!H27:H32) | H15: =SUM('📋 Детальный реестр'!G27:G32) | I15: =SUM('📋 Детальный реестр'!I27:I32) | J15: =SUM('📋 Детальный реестр'!M27:M32) | K15: =INDEX('🔍 Аудит и сверка спецов'!I7, 1)
B16: 6 | C16: =INDEX('📋 Детальный реестр'!B33:B38, 1) | D16: =INDEX('📋 Детальный реестр'!C33:C38, 1) | E16: =COUNTIF('📋 Детальный реестр'!F33:F38, "Активен") | F16: =COUNTIF('📋 Детальный реестр'!F33:F38, "БАН") | G16: =SUM('📋 Детальный реестр'!H33:H38) | H16: =SUM('📋 Детальный реестр'!G33:G38) | I16: =SUM('📋 Детальный реестр'!I33:I38) | J16: =SUM('📋 Детальный реестр'!M33:M38) | K16: =INDEX('🔍 Аудит и сверка спецов'!I8, 1)
B17: 7 | C17: =INDEX('📋 Детальный реестр'!B39:B44, 1) | D17: =INDEX('📋 Детальный реестр'!C39:C44, 1) | E17: =COUNTIF('📋 Детальный реестр'!F39:F44, "Активен") | F17: =COUNTIF('📋 Детальный реестр'!F39:F44, "БАН") | G17: =SUM('📋 Детальный реестр'!H39:H44) | H17: =SUM('📋 Детальный реестр'!G39:G44) | I17: =SUM('📋 Детальный реестр'!I39:I44) | J17: =SUM('📋 Детальный реестр'!M39:M44) | K17: =INDEX('🔍 Аудит и сверка спецов'!I9, 1)
B18: 8 | C18: =INDEX('📋 Детальный реестр'!B45:B50, 1) | D18: =INDEX('📋 Детальный реестр'!C45:C50, 1) | E18: =COUNTIF('📋 Детальный реестр'!F45:F50, "Активен") | F18: =COUNTIF('📋 Детальный реестр'!F45:F50, "БАН") | G18: =SUM('📋 Детальный реестр'!H45:H50) | H18: =SUM('📋 Детальный реестр'!G45:G50) | I18: =SUM('📋 Детальный реестр'!I45:I50) | J18: =SUM('📋 Детальный реестр'!M45:M50) | K18: =INDEX('🔍 Аудит и сверка спецов'!I10, 1)
B19: 9 | C19: =INDEX('📋 Детальный реестр'!B51:B56, 1) | D19: =INDEX('📋 Детальный реестр'!C51:C56, 1) | E19: =COUNTIF('📋 Детальный реестр'!F51:F56, "Активен") | F19: =COUNTIF('📋 Детальный реестр'!F51:F56, "БАН") | G19: =SUM('📋 Детальный реестр'!H51:H56) | H19: =SUM('📋 Детальный реестр'!G51:G56) | I19: =SUM('📋 Детальный реестр'!I51:I56) | J19: =SUM('📋 Детальный реестр'!M51:M56) | K19: =INDEX('🔍 Аудит и сверка спецов'!I11, 1)
B20: 10 | C20: =INDEX('📋 Детальный реестр'!B57:B62, 1) | D20: =INDEX('📋 Детальный реестр'!C57:C62, 1) | E20: =COUNTIF('📋 Детальный реестр'!F57:F62, "Активен") | F20: =COUNTIF('📋 Детальный реестр'!F57:F62, "БАН") | G20: =SUM('📋 Детальный реестр'!H57:H62) | H20: =SUM('📋 Детальный реестр'!G57:G62) | I20: =SUM('📋 Детальный реестр'!I57:I62) | J20: =SUM('📋 Детальный реестр'!M57:M62) | K20: =INDEX('🔍 Аудит и сверка спецов'!I12, 1)
C21: ИТОГО | D21: — | E21: =SUM(E11:E20) | F21: =SUM(F11:F20) | G21: =SUM(G11:G20) | H21: =SUM(H11:H20) | I21: =SUM(I11:I20) | J21: =SUM(J11:J20) | K21: —

Sheet 📋 Детальный реестр
A2: № | B2: Инфлюенсер | C2: Ответственный спец | D2: Соцсеть | E2: Ссылка / Handle | F2: Статус аккаунта | G2: Всего постов | H2: Постов за день (10-19ч) | I2: Общие просмотры | J2: Просмотры посл. поста | K2: Лайки посл. поста | L2: Дата/время посл. поста | M2: Подписчики | N2: Прирост подписчиков | O2: Всего лайков | P2: ХОТ ПОСТ (Ссылка) | Q2: ХОТ ПОСТ (Просмотры) | R2: Примечание
A3: 1 | B3: Алеся Бут (Беларусь) | C3: Лёша | D3: TikTok | E3: https://www.tiktok.com/@yanveras13 | F3: Активен | G3: 7 | H3: 0 | I3: 5268 | J3: 136 | K3: 0 | L3: 04.09.2026 | M3: 12 | N3: 0 | O3: 552 | P3: https://www.tiktok.com/@yanveras13/video/7680108719144799508 | Q3: 2906 | R3: Email: alesyabyt18@gmail.com | Pass: 123Byt123 | SocPass: 123Byt123!
A4: 2 | B4: Алеся Бут (Беларусь) | C4: Лёша | D4: YouTube | E4: https://youtube.com/channel/UCn-t5Z16uoP60hkWQQ7d_Tg | F4: Активен | G4: 5 | H4: 0 | I4: 8403 | J4: 0 | K4: 0 | L4: 04.09.2026 | M4: 4 | N4: 0 | O4: 0 | Q4: 5000 | R4: Email: alesyabyt18@gmail.com | Pass: 123Byt123 | SocPass: 123Byt123!
A5: 3 | B5: Алеся Бут (Беларусь) | C5: Лёша | D5: Instagram | E5: https://www.instagram.com/anveras509 | F5: Активен | G5: 5 | H5: 0 | I5: 1069 | J5: 0 | K5: 0 | L5: 04.09.2026 | M5: 1 | N5: 0 | O5: 0 | Q5: 412 | R5: Email: alesyabyt18@gmail.com | Pass: 123Byt123 | SocPass: 123Byt123!
A6: 4 | B6: Алеся Бут (Беларусь) | C6: Лёша | D6: Facebook | E6: https://www.facebook.com/share/1BMagQvaoE/ | F6: Активен | G6: 5 | H6: 0 | I6: 718 | J6: 43 | K6: 0 | L6: 04.09.2026 | M6: 0 | N6: 0 | O6: 0 | Q6: 280 | R6: Email: alesyabyt18@gmail.com | Pass: 123Byt123 | SocPass: 123Byt123!
A7: 5 | B7: Алеся Бут (Беларусь) | C7: Лёша | D7: Threads | E7: https://www.threads.net/@alesabut | F7: Активен | G7: 3 | H7: 0 | I7: 0 | J7: 0 | K7: 0 | L7: 04.09.2026 | M7: 0 | N7: 0 | O7: 0 | Q7: 0 | R7: Email: alesyabyt18@gmail.com | Pass: 123Byt123 | SocPass: 123Byt123!
A8: 6 | B8: Алеся Бут (Беларусь) | C8: Лёша | D8: X (Twitter) | E8: https://x.com/ft73v5 | F8: Активен | G8: 2 | H8: 0 | I8: 0 | J8: 0 | K8: 0 | L8: 04.09.2026 | M8: 0 | N8: 0 | O8: 0 | Q8: 0 | R8: Email: alesyabyt18@gmail.com | Pass: 123Byt123 | SocPass: 123Byt123!
A9: 7 | B9: Ян Верса (Беларусь) | C9: Лёша | D9: TikTok | E9: https://www.tiktok.com/@alesyabyt | F9: Активен | G9: 6 | H9: 0 | I9: 3605 | J9: 550 | K9: 0 | L9: 04.09.2026 | M9: 0 | N9: 0 | O9: 89 | P9: https://www.tiktok.com/@alesyabyt/video/7679108870115052807 | Q9: 1056 | R9: Email: anveras5098@gmail.com | Pass: 123Yan123 | SocPass: 123Yan123!
A10: 8 | B10: Ян Верса (Беларусь) | C10: Лёша | D10: YouTube | E10: https://youtube.com/channel/UCxgk7mDrX45Wb9Wv61hO75w | F10: Активен | G10: 5 | H10: 0 | I10: 4200 | J10: 0 | K10: 0 | L10: 04.09.2026 | M10: 6 | N10: 0 | O10: 0 | Q10: 1100 | R10: Email: anveras5098@gmail.com | Pass: 123Yan123 | SocPass: 123Yan123!
A11: 9 | B11: Ян Верса (Беларусь) | C11: Лёша | D11: Instagram | E11: https://www.instagram.com/alesabut | F11: Активен | G11: 5 | H11: 0 | I11: 1620 | J11: 0 | K11: 0 | L11: 04.09.2026 | M11: 2 | N11: 0 | O11: 0 | Q11: 661 | R11: Email: anveras5098@gmail.com | Pass: 123Yan123 | SocPass: 123Yan123!
A12: 10 | B12: Ян Верса (Беларусь) | C12: Лёша | D12: Facebook | E12: https://www.facebook.com/share/1GbKg4Tp5n/ | F12: Активен | G12: 5 | H12: 0 | I12: 248 | J12: 0 | K12: 0 | L12: 04.09.2026 | M12: 0 | N12: 0 | O12: 0 | Q12: 0 | R12: Email: anveras5098@gmail.com | Pass: 123Yan123 | SocPass: 123Yan123!
A13: 11 | B13: Ян Верса (Беларусь) | C13: Лёша | D13: Threads | E13: https://www.threads.net/@anveras509 | F13: Активен | G13: 3 | H13: 0 | I13: 0 | J13: 0 | K13: 0 | L13: 04.09.2026 | M13: 509 | N13: 0 | O13: 0 | Q13: 0 | R13: Email: anveras5098@gmail.com | Pass: 123Yan123 | SocPass: 123Yan123!
A14: 12 | B14: Ян Верса (Беларусь) | C14: Лёша | D14: X (Twitter) | E14: https://x.com/neaz8b | F14: Активен | G14: 3 | H14: 0 | I14: 0 | J14: 0 | K14: 0 | L14: 04.09.2026 | M14: 0 | N14: 0 | O14: 0 | Q14: 0 | R14: Email: anveras5098@gmail.com | Pass: 123Yan123 | SocPass: 123Yan123!
A15: 13 | B15: Baraka Otieno (Кения) | C15: Саша | D15: TikTok | E15: https://www.tiktok.com/@baraka.otieno8 | F15: Активен | G15: 6 | H15: 0 | I15: 3267 | J15: 47 | K15: 0 | L15: 04.09.2026 | M15: 3 | N15: 0 | O15: 106 | P15: https://www.tiktok.com/@baraka.otieno8/video/7680945027325005064 | Q15: 875 | R15: Email: otienobaraka20@gmail.com | Pass: O))))))1
A16: 14 | B16: Baraka Otieno (Кения) | C16: Саша | D16: YouTube | E16: https://www.youtube.com/@BarakaOtieno-t9y | F16: Активен | G16: 1 | H16: 0 | I16: 2 | J16: 0 | K16: 0 | L16: 04.09.2026 | M16: 0 | N16: 0 | O16: 0 | Q16: 2 | R16: Email: otienobaraka20@gmail.com | Pass: O))))))1
A17: 15 | B17: Baraka Otieno (Кения) | C17: Саша | D17: Instagram | E17: https://www.instagram.com/otienobarakaa | F17: Активен | G17: 0 | H17: 0 | I17: 0 | J17: 0 | K17: 0 | L17: 04.09.2026 | M17: 1 | N17: 0 | O17: 0 | Q17: 0 | R17: Email: otienobaraka20@gmail.com | Pass: O))))))1
A18: 16 | B18: Baraka Otieno (Кения) | C18: Саша | D18: Facebook | E18: https://www.facebook.com/profile.php?id=61594225224413 | F18: Активен | G18: 0 | H18: 0 | I18: 0 | J18: 0 | K18: 0 | L18: 04.09.2026 | M18: 0 | N18: 0 | O18: 0 | Q18: 0 | R18: Email: otienobaraka20@gmail.com | Pass: O))))))1
A19: 17 | B19: Baraka Otieno (Кения) | C19: Саша | D19: Threads | E19: https://www.threads.net/@otienobarakaa | F19: Активен | G19: 0 | H19: 0 | I19: 0 | J19: 0 | K19: 0 | L19: 04.09.2026 | M19: 0 | N19: 0 | O19: 0 | Q19: 0 | R19: Email: otienobaraka20@gmail.com | Pass: O))))))1
A20: 18 | B20: Baraka Otieno (Кения) | C20: Саша | D20: X (Twitter) | F20: Нет ссылки | G20: 0 | H20: 0 | I20: 0 | J20: 0 | K20: 0 | L20: 04.09.2026 | M20: 0 | N20: 0 | O20: 0 | Q20: 0 | R20: Email: otienobaraka20@gmail.com | Pass: O))))))1
A21: 19 | B21: Grace Muthioni (Кения) | C21: Саша | D21: TikTok | E21: https://www.tiktok.com/@grace.muthioni | F21: Активен | G21: 6 | H21: 0 | I21: 1516 | J21: 52 | K21: 0 | L21: 04.09.2026 | M21: 3 | N21: 0 | O21: 60 | P21: https://www.tiktok.com/@grace.muthioni/video/7681208753944907028 | Q21: 528 | R21: Email: muthionig@gmail.com | Pass: M))))))1
A22: 20 | B22: Grace Muthioni (Кения) | C22: Саша | D22: YouTube | E22: https://www.youtube.com/@GraceMuthioni | F22: Активен | G22: 1 | H22: 0 | I22: 11 | J22: 7 | K22: 0 | L22: 04.09.2026 | M22: 0 | N22: 0 | O22: 0 | Q22: 11 | R22: Email: muthionig@gmail.com | Pass: M))))))1
A23: 21 | B23: Grace Muthioni (Кения) | C23: Саша | D23: Instagram | E23: https://www.instagram.com/gracemuthioni | F23: Активен | G23: 0 | H23: 0 | I23: 0 | J23: 0 | K23: 0 | L23: 04.09.2026 | M23: 2 | N23: 0 | O23: 0 | Q23: 0 | R23: Email: muthionig@gmail.com | Pass: M))))))1
A24: 22 | B24: Grace Muthioni (Кения) | C24: Саша | D24: Facebook | E24: https://www.facebook.com/share/19Yipg1q9R/ | F24: Активен | G24: 0 | H24: 0 | I24: 0 | J24: 0 | K24: 0 | L24: 04.09.2026 | M24: 0 | N24: 0 | O24: 0 | Q24: 0 | R24: Email: muthionig@gmail.com | Pass: M))))))1
A25: 23 | B25: Grace Muthioni (Кения) | C25: Саша | D25: Threads | E25: https://www.threads.net/@gracemuthioni | F25: Активен | G25: 0 | H25: 0 | I25: 0 | J25: 0 | K25: 0 | L25: 04.09.2026 | M25: 0 | N25: 0 | O25: 0 | Q25: 0 | R25: Email: muthionig@gmail.com | Pass: M))))))1
A26: 24 | B26: Grace Muthioni (Кения) | C26: Саша | D26: X (Twitter) | F26: Нет ссылки | G26: 0 | H26: 0 | I26: 0 | J26: 0 | K26: 0 | L26: 04.09.2026 | M26: 0 | N26: 0 | O26: 0 | Q26: 0 | R26: Email: muthionig@gmail.com | Pass: M))))))1
A27: 25 | B27: Kaan Turan (Турция) | C27: Саша | D27: TikTok | E27: https://www.tiktok.com/@kaan.turan225 | F27: Активен | G27: 9 | H27: 0 | I27: 5342 | J27: 179 | K27: 0 | L27: 04.09.2026 | M27: 5 | N27: 0 | O27: 89 | P27: https://www.tiktok.com/@kaan.turan225/video/7681297652310412562 | Q27: 1089 | R27: Email: kaanturaaan@gmail.com | Pass: K))))))1
A28: 26 | B28: Kaan Turan (Турция) | C28: Саша | D28: YouTube | E28: https://www.youtube.com/@KAANTURAN-e5k | F28: Активен | G28: 2 | H28: 0 | I28: 377 | J28: 110 | K28: 0 | L28: 04.09.2026 | M28: 0 | N28: 0 | O28: 0 | Q28: 272 | R28: Email: kaanturaaan@gmail.com | Pass: K))))))1
A29: 27 | B29: Kaan Turan (Турция) | C29: Саша | D29: Instagram | E29: Бан | F29: БАН | G29: 0 | H29: 0 | I29: 0 | J29: 0 | K29: 0 | L29: 04.09.2026 | M29: 0 | N29: 0 | O29: 0 | Q29: 0 | R29: Email: kaanturaaan@gmail.com | Pass: K))))))1
A30: 28 | B30: Kaan Turan (Турция) | C30: Саша | D30: Facebook | E30: Бан | F30: БАН | G30: 0 | H30: 0 | I30: 0 | J30: 0 | K30: 0 | L30: 04.09.2026 | M30: 0 | N30: 0 | O30: 0 | Q30: 0 | R30: Email: kaanturaaan@gmail.com | Pass: K))))))1
A31: 29 | B31: Kaan Turan (Турция) | C31: Саша | D31: Threads | E31: Бан | F31: БАН | G31: 0 | H31: 0 | I31: 0 | J31: 0 | K31: 0 | L31: 04.09.2026 | M31: 0 | N31: 0 | O31: 0 | Q31: 0 | R31: Email: kaanturaaan@gmail.com | Pass: K))))))1
A32: 30 | B32: Kaan Turan (Турция) | C32: Саша | D32: X (Twitter) | F32: Нет ссылки | G32: 0 | H32: 0 | I32: 0 | J32: 0 | K32: 0 | L32: 04.09.2026 | M32: 0 | N32: 0 | O32: 0 | Q32: 0 | R32: Email: kaanturaaan@gmail.com | Pass: K))))))1
A33: 31 | B33: Melissa Kara (Турция) | C33: Саша | D33: TikTok | E33: https://www.tiktok.com/@melissa.kara47 | F33: Активен | G33: 9 | H33: 0 | I33: 4418 | J33: 44 | K33: 0 | L33: 04.09.2026 | M33: 6 | N33: 0 | O33: 77 | P33: https://www.tiktok.com/@melissa.kara47/video/7680583510163344661 | Q33: 794 | R33: Email: lexivargo6@gmail.com | Pass: L))))))1
A34: 32 | B34: Melissa Kara (Турция) | C34: Саша | D34: YouTube | E34: https://www.youtube.com/@MelissaKaraaa | F34: Активен | G34: 2 | H34: 0 | I34: 1398 | J34: 289 | K34: 0 | L34: 04.09.2026 | M34: 1 | N34: 0 | O34: 0 | Q34: 1100 | R34: Email: lexivargo6@gmail.com | Pass: L))))))1
A35: 33 | B35: Melissa Kara (Турция) | C35: Саша | D35: Instagram | E35: Бан | F35: БАН | G35: 0 | H35: 0 | I35: 0 | J35: 0 | K35: 0 | L35: 04.09.2026 | M35: 0 | N35: 0 | O35: 0 | Q35: 0 | R35: Email: lexivargo6@gmail.com | Pass: L))))))1
A36: 34 | B36: Melissa Kara (Турция) | C36: Саша | D36: Facebook | E36: Бан | F36: БАН | G36: 0 | H36: 0 | I36: 0 | J36: 0 | K36: 0 | L36: 04.09.2026 | M36: 0 | N36: 0 | O36: 0 | Q36: 0 | R36: Email: lexivargo6@gmail.com | Pass: L))))))1
A37: 35 | B37: Melissa Kara (Турция) | C37: Саша | D37: Threads | E37: Бан | F37: БАН | G37: 0 | H37: 0 | I37: 0 | J37: 0 | K37: 0 | L37: 04.09.2026 | M37: 0 | N37: 0 | O37: 0 | Q37: 0 | R37: Email: lexivargo6@gmail.com | Pass: L))))))1
A38: 36 | B38: Melissa Kara (Турция) | C38: Саша | D38: X (Twitter) | F38: Нет ссылки | G38: 0 | H38: 0 | I38: 0 | J38: 0 | K38: 0 | L38: 04.09.2026 | M38: 0 | N38: 0 | O38: 0 | Q38: 0 | R38: Email: lexivargo6@gmail.com | Pass: L))))))1
A39: 37 | B39: Асель Исакова (Кыргызстан) | C39: Сёма | D39: TikTok | E39: https://www.tiktok.com/@asel.isakova.077 | F39: Активен | G39: 9 | H39: 0 | I39: 32791 | J39: 56 | K39: 0 | L39: 04.09.2026 | M39: 96 | N39: 0 | O39: 2004 | P39: https://www.tiktok.com/@asel.isakova.077/video/7680600263341706514 | Q39: 21100
A40: 38 | B40: Асель Исакова (Кыргызстан) | C40: Сёма | D40: YouTube | E40: https://www.youtube.com/@%D0%90%D1%81%D0%B5%D0%BB%D1%8C%D0%98%D1%81%D0%B0%D0%BA%D0%BE%D0%B2%D0%B0-%D1%824%D1%86 | F40: Активен | G40: 8 | H40: 0 | I40: 730629 | J40: 9 | K40: 0 | L40: 04.09.2026 | M40: 801 | N40: 0 | O40: 0 | Q40: 440000
A41: 39 | B41: Асель Исакова (Кыргызстан) | C41: Сёма | D41: Instagram | E41: https://www.instagram.com/aseli_sakova?igsi=MTFvN2w4cHl2enQ2bg== | F41: Активен | G41: 7 | H41: 0 | I41: 0 | J41: 0 | K41: 0 | L41: 04.09.2026 | M41: 4 | N41: 0 | O41: 0 | Q41: 0
...

Sheet 🔍 Аудит и сверка спецов
A1: МОДУЛЬ СВЕРКИ И АНТИФРОДА: ЗАЯВЛЕНИЯ СПЕЦИАЛИСТОВ VS РЕАЛЬНЫЕ ФАКТЫ
A2: № | B2: Ответственный спец | C2: Инфлюенсер | D2: Спец заявил: видео | E2: Факт в сетке (10-19ч) | F2: Разница (Факт - План) | G2: Спец заявил: баны | H2: Факт банов в сетке | I2: Статус сверки | J2: Штраф / Примечание
A3: 1 | B3: =INDEX('📋 Детальный реестр'!C3:C8, 1) | C3: =INDEX('📋 Детальный реестр'!B3:B8, 1) | D3: 0 | E3: =SUM('📋 Детальный реестр'!H3:H8) | F3: =E3-D3 | G3: 0 | H3: =COUNTIF('📋 Детальный реестр'!F3:F8, "БАН") | I3: =IF(D3=0, "Ожидает отчета", IF(E3>=D3, "🟢 Совпадает", IF(E3<D3, "🔴 НАЕБ / НЕДОЛИВ", "🟡 Расхождение")))
A4: 2 | B4: =INDEX('📋 Детальный реестр'!C9:C14, 1) | C4: =INDEX('📋 Детальный реестр'!B9:B14, 1) | D4: 0 | E4: =SUM('📋 Детальный реестр'!H9:H14) | F4: =E4-D4 | G4: 0 | H4: =COUNTIF('📋 Детальный реестр'!F9:F14, "БАН") | I4: =IF(D4=0, "Ожидает отчета", IF(E4>=D4, "🟢 Совпадает", IF(E4<D4, "🔴 НАЕБ / НЕДОЛИВ", "🟡 Расхождение")))
A5: 3 | B5: =INDEX('📋 Детальный реестр'!C15:C20, 1) | C5: =INDEX('📋 Детальный реестр'!B15:B20, 1) | D5: 0 | E5: =SUM('📋 Детальный реестр'!H15:H20) | F5: =E5-D5 | G5: 0 | H5: =COUNTIF('📋 Детальный реестр'!F15:F20, "БАН") | I5: =IF(D5=0, "Ожидает отчета", IF(E5>=D5, "🟢 Совпадает", IF(E5<D5, "🔴 НАЕБ / НЕДОЛИВ", "🟡 Расхождение")))
A6: 4 | B6: =INDEX('📋 Детальный реестр'!C21:C26, 1) | C6: =INDEX('📋 Детальный реестр'!B21:B26, 1) | D6: 0 | E6: =SUM('📋 Детальный реестр'!H21:H26) | F6: =E6-D6 | G6: 0 | H6: =COUNTIF('📋 Детальный реестр'!F21:F26, "БАН") | I6: =IF(D6=0, "Ожидает отчета", IF(E6>=D6, "🟢 Совпадает", IF(E6<D6, "🔴 НАЕБ / НЕДОЛИВ", "🟡 Расхождение")))
A7: 5 | B7: =INDEX('📋 Детальный реестр'!C27:C32, 1) | C7: =INDEX('📋 Детальный реестр'!B27:B32, 1) | D7: 0 | E7: =SUM('📋 Детальный реестр'!H27:H32) | F7: =E7-D7 | G7: 0 | H7: =COUNTIF('📋 Детальный реестр'!F27:F32, "БАН") | I7: =IF(D7=0, "Ожидает отчета", IF(E7>=D7, "🟢 Совпадает", IF(E7<D7, "🔴 НАЕБ / НЕДОЛИВ", "🟡 Расхождение")))
A8: 6 | B8: =INDEX('📋 Детальный реестр'!C33:C38, 1) | C8: =INDEX('📋 Детальный реестр'!B33:B38, 1) | D8: 0 | E8: =SUM('📋 Детальный реестр'!H33:H38) | F8: =E8-D8 | G8: 0 | H8: =COUNTIF('📋 Детальный реестр'!F33:F38, "БАН") | I8: =IF(D8=0, "Ожидает отчета", IF(E8>=D8, "🟢 Совпадает", IF(E8<D8, "🔴 НАЕБ / НЕДОЛИВ", "🟡 Расхождение")))
A9: 7 | B9: =INDEX('📋 Детальный реестр'!C39:C44, 1) | C9: =INDEX('📋 Детальный реестр'!B39:B44, 1) | D9: 0 | E9: =SUM('📋 Детальный реестр'!H39:H44) | F9: =E9-D9 | G9: 0 | H9: =COUNTIF('📋 Детальный реестр'!F39:F44, "БАН") | I9: =IF(D9=0, "Ожидает отчета", IF(E9>=D9, "🟢 Совпадает", IF(E9<D9, "🔴 НАЕБ / НЕДОЛИВ", "🟡 Расхождение")))
A10: 8 | B10: =INDEX('📋 Детальный реестр'!C45:C50, 1) | C10: =INDEX('📋 Детальный реестр'!B45:B50, 1) | D10: 0 | E10: =SUM('📋 Детальный реестр'!H45:H50) | F10: =E10-D10 | G10: 0 | H10: =COUNTIF('📋 Детальный реестр'!F45:F50, "БАН") | I10: =IF(D10=0, "Ожидает отчета", IF(E10>=D10, "🟢 Совпадает", IF(E10<D10, "🔴 НАЕБ / НЕДОЛИВ", "🟡 Расхождение")))
A11: 9 | B11: =INDEX('📋 Детальный реестр'!C51:C56, 1) | C11: =INDEX('📋 Детальный реестр'!B51:B56, 1) | D11: 0 | E11: =SUM('📋 Детальный реестр'!H51:H56) | F11: =E11-D11 | G11: 0 | H11: =COUNTIF('📋 Детальный реестр'!F51:F56, "БАН") | I11: =IF(D11=0, "Ожидает отчета", IF(E11>=D11, "🟢 Совпадает", IF(E11<D11, "🔴 НАЕБ / НЕДОЛИВ", "🟡 Расхождение")))
A12: 10 | B12: =INDEX('📋 Детальный реестр'!C57:C62, 1) | C12: =INDEX('📋 Детальный реестр'!B57:B62, 1) | D12: 0 | E12: =SUM('📋 Детальный реестр'!H57:H62) | F12: =E12-D12 | G12: 0 | H12: =COUNTIF('📋 Детальный реестр'!F57:F62, "БАН") | I12: =IF(D12=0, "Ожидает отчета", IF(E12>=D12, "🟢 Совпадает", IF(E12<D12, "🔴 НАЕБ / НЕДОЛИВ", "🟡 Расхождение")))
